 2023-12-11 12:37:56,147 - DEBUG - Starting new HTTPS connection (1): api.telegram.org:443
 2023-12-11 12:37:56,609 - DEBUG - https://api.telegram.org:443 "GET /bot1548279772:AAFHf8ChEdDIsunUEFiSI7r_-JF-lKwBuMw/getMe HTTP/1.1" 200 197
 2023-12-11 12:37:56,611 - DEBUG - Starting new HTTPS connection (1): api.telegram.org:443
 2023-12-11 12:38:00,474 - DEBUG - https://api.telegram.org:443 "GET /bot1548279772:AAFHf8ChEdDIsunUEFiSI7r_-JF-lKwBuMw/getUpdates?offset=1&timeout=20 HTTP/1.1" 409 143
 2023-12-11 12:38:00,512 - ERROR - Threaded polling exception: A request to the Telegram API was unsuccessful. Error code: 409. Description: Conflict: terminated by other getUpdates request; make sure that only one bot instance is running
 2023-12-11 12:38:00,513 - ERROR - Exception traceback:
Traceback (most recent call last):
  File "C:\Users\qpjlygujlkOo\AppData\Local\Packages\PythonSoftwareFoundation.Python.3.11_qbz5n2kfra8p0\LocalCache\local-packages\Python311\site-packages\telebot\__init__.py", line 1073, in __threaded_polling
    polling_thread.raise_exceptions()
  File "C:\Users\qpjlygujlkOo\AppData\Local\Packages\PythonSoftwareFoundation.Python.3.11_qbz5n2kfra8p0\LocalCache\local-packages\Python311\site-packages\telebot\util.py", line 108, in raise_exceptions
    raise self.exception_info
  File "C:\Users\qpjlygujlkOo\AppData\Local\Packages\PythonSoftwareFoundation.Python.3.11_qbz5n2kfra8p0\LocalCache\local-packages\Python311\site-packages\telebot\util.py", line 90, in run
    task(*args, **kwargs)
  File "C:\Users\qpjlygujlkOo\AppData\Local\Packages\PythonSoftwareFoundation.Python.3.11_qbz5n2kfra8p0\LocalCache\local-packages\Python311\site-packages\telebot\__init__.py", line 649, in __retrieve_updates
    updates = self.get_updates(offset=(self.last_update_id + 1),
             ^^^^^^^^^^^^^^^^^^^^^^^^^^^^^^^^^^^^^^^^^^^^^^^^^^
  File "C:\Users\qpjlygujlkOo\AppData\Local\Packages\PythonSoftwareFoundation.Python.3.11_qbz5n2kfra8p0\LocalCache\local-packages\Python311\site-packages\telebot\__init__.py", line 623, in get_updates
    json_updates = apihelper.get_updates(self.token, offset, limit, timeout, allowed_updates, long_polling_timeout)
                   ^^^^^^^^^^^^^^^^^^^^^^^^^^^^^^^^^^^^^^^^^^^^^^^^^^^^^^^^^^^^^^^^^^^^^^^^^^^^^^^^^^^^^^^^^^^^^^^^
  File "C:\Users\qpjlygujlkOo\AppData\Local\Packages\PythonSoftwareFoundation.Python.3.11_qbz5n2kfra8p0\LocalCache\local-packages\Python311\site-packages\telebot\apihelper.py", line 321, in get_updates
    return _make_request(token, method_url, params=payload)
           ^^^^^^^^^^^^^^^^^^^^^^^^^^^^^^^^^^^^^^^^^^^^^^^^
  File "C:\Users\qpjlygujlkOo\AppData\Local\Packages\PythonSoftwareFoundation.Python.3.11_qbz5n2kfra8p0\LocalCache\local-packages\Python311\site-packages\telebot\apihelper.py", line 162, in _make_request
    json_result = _check_result(method_name, result)
                  ^^^^^^^^^^^^^^^^^^^^^^^^^^^^^^^^^^
  File "C:\Users\qpjlygujlkOo\AppData\Local\Packages\PythonSoftwareFoundation.Python.3.11_qbz5n2kfra8p0\LocalCache\local-packages\Python311\site-packages\telebot\apihelper.py", line 189, in _check_result
    raise ApiTelegramException(method_name, result, result_json)
telebot.apihelper.ApiTelegramException: A request to the Telegram API was unsuccessful. Error code: 409. Description: Conflict: terminated by other getUpdates request; make sure that only one bot instance is running

