 2023-12-18 09:48:49,134 - DEBUG - Starting new HTTPS connection (1): api.telegram.org:443
 2023-12-18 09:48:51,261 - DEBUG - https://api.telegram.org:443 "GET /bot1548279772:AAFHf8ChEdDIsunUEFiSI7r_-JF-lKwBuMw/getMe HTTP/1.1" 401 58
 2023-12-18 09:48:51,261 - ERROR - Infinity polling exception: A request to the Telegram API was unsuccessful. Error code: 401. Description: Unauthorized
 2023-12-18 09:48:51,292 - ERROR - Exception traceback:
Traceback (most recent call last):
  File "C:\Users\qpjlygujlkOo\AppData\Local\Packages\PythonSoftwareFoundation.Python.3.11_qbz5n2kfra8p0\LocalCache\local-packages\Python311\site-packages\telebot\__init__.py", line 955, in infinity_polling
    self.polling(non_stop=True, timeout=timeout, long_polling_timeout=long_polling_timeout,
  File "C:\Users\qpjlygujlkOo\AppData\Local\Packages\PythonSoftwareFoundation.Python.3.11_qbz5n2kfra8p0\LocalCache\local-packages\Python311\site-packages\telebot\__init__.py", line 1040, in polling
    logger.info('Starting your bot with username: [@%s]', self.user.username)
                                                          ^^^^^^^^^
  File "C:\Users\qpjlygujlkOo\AppData\Local\Packages\PythonSoftwareFoundation.Python.3.11_qbz5n2kfra8p0\LocalCache\local-packages\Python311\site-packages\telebot\__init__.py", line 273, in user
    self._user = self.get_me()
                 ^^^^^^^^^^^^^
  File "C:\Users\qpjlygujlkOo\AppData\Local\Packages\PythonSoftwareFoundation.Python.3.11_qbz5n2kfra8p0\LocalCache\local-packages\Python311\site-packages\telebot\__init__.py", line 1236, in get_me
    result = apihelper.get_me(self.token)
             ^^^^^^^^^^^^^^^^^^^^^^^^^^^^
  File "C:\Users\qpjlygujlkOo\AppData\Local\Packages\PythonSoftwareFoundation.Python.3.11_qbz5n2kfra8p0\LocalCache\local-packages\Python311\site-packages\telebot\apihelper.py", line 196, in get_me
    return _make_request(token, method_url)
           ^^^^^^^^^^^^^^^^^^^^^^^^^^^^^^^^
  File "C:\Users\qpjlygujlkOo\AppData\Local\Packages\PythonSoftwareFoundation.Python.3.11_qbz5n2kfra8p0\LocalCache\local-packages\Python311\site-packages\telebot\apihelper.py", line 162, in _make_request
    json_result = _check_result(method_name, result)
                  ^^^^^^^^^^^^^^^^^^^^^^^^^^^^^^^^^^
  File "C:\Users\qpjlygujlkOo\AppData\Local\Packages\PythonSoftwareFoundation.Python.3.11_qbz5n2kfra8p0\LocalCache\local-packages\Python311\site-packages\telebot\apihelper.py", line 189, in _check_result
    raise ApiTelegramException(method_name, result, result_json)
telebot.apihelper.ApiTelegramException: A request to the Telegram API was unsuccessful. Error code: 401. Description: Unauthorized

 2023-12-18 09:48:54,344 - DEBUG - https://api.telegram.org:443 "GET /bot1548279772:AAFHf8ChEdDIsunUEFiSI7r_-JF-lKwBuMw/getMe HTTP/1.1" 401 58
 2023-12-18 09:48:54,344 - ERROR - Infinity polling exception: A request to the Telegram API was unsuccessful. Error code: 401. Description: Unauthorized
 2023-12-18 09:48:54,345 - ERROR - Exception traceback:
Traceback (most recent call last):
  File "C:\Users\qpjlygujlkOo\AppData\Local\Packages\PythonSoftwareFoundation.Python.3.11_qbz5n2kfra8p0\LocalCache\local-packages\Python311\site-packages\telebot\__init__.py", line 955, in infinity_polling
    self.polling(non_stop=True, timeout=timeout, long_polling_timeout=long_polling_timeout,
  File "C:\Users\qpjlygujlkOo\AppData\Local\Packages\PythonSoftwareFoundation.Python.3.11_qbz5n2kfra8p0\LocalCache\local-packages\Python311\site-packages\telebot\__init__.py", line 1040, in polling
    logger.info('Starting your bot with username: [@%s]', self.user.username)
                                                          ^^^^^^^^^
  File "C:\Users\qpjlygujlkOo\AppData\Local\Packages\PythonSoftwareFoundation.Python.3.11_qbz5n2kfra8p0\LocalCache\local-packages\Python311\site-packages\telebot\__init__.py", line 273, in user
    self._user = self.get_me()
                 ^^^^^^^^^^^^^
  File "C:\Users\qpjlygujlkOo\AppData\Local\Packages\PythonSoftwareFoundation.Python.3.11_qbz5n2kfra8p0\LocalCache\local-packages\Python311\site-packages\telebot\__init__.py", line 1236, in get_me
    result = apihelper.get_me(self.token)
             ^^^^^^^^^^^^^^^^^^^^^^^^^^^^
  File "C:\Users\qpjlygujlkOo\AppData\Local\Packages\PythonSoftwareFoundation.Python.3.11_qbz5n2kfra8p0\LocalCache\local-packages\Python311\site-packages\telebot\apihelper.py", line 196, in get_me
    return _make_request(token, method_url)
           ^^^^^^^^^^^^^^^^^^^^^^^^^^^^^^^^
  File "C:\Users\qpjlygujlkOo\AppData\Local\Packages\PythonSoftwareFoundation.Python.3.11_qbz5n2kfra8p0\LocalCache\local-packages\Python311\site-packages\telebot\apihelper.py", line 162, in _make_request
    json_result = _check_result(method_name, result)
                  ^^^^^^^^^^^^^^^^^^^^^^^^^^^^^^^^^^
  File "C:\Users\qpjlygujlkOo\AppData\Local\Packages\PythonSoftwareFoundation.Python.3.11_qbz5n2kfra8p0\LocalCache\local-packages\Python311\site-packages\telebot\apihelper.py", line 189, in _check_result
    raise ApiTelegramException(method_name, result, result_json)
telebot.apihelper.ApiTelegramException: A request to the Telegram API was unsuccessful. Error code: 401. Description: Unauthorized

 2023-12-18 09:48:57,398 - DEBUG - https://api.telegram.org:443 "GET /bot1548279772:AAFHf8ChEdDIsunUEFiSI7r_-JF-lKwBuMw/getMe HTTP/1.1" 401 58
 2023-12-18 09:48:57,398 - ERROR - Infinity polling exception: A request to the Telegram API was unsuccessful. Error code: 401. Description: Unauthorized
 2023-12-18 09:48:57,399 - ERROR - Exception traceback:
Traceback (most recent call last):
  File "C:\Users\qpjlygujlkOo\AppData\Local\Packages\PythonSoftwareFoundation.Python.3.11_qbz5n2kfra8p0\LocalCache\local-packages\Python311\site-packages\telebot\__init__.py", line 955, in infinity_polling
    self.polling(non_stop=True, timeout=timeout, long_polling_timeout=long_polling_timeout,
  File "C:\Users\qpjlygujlkOo\AppData\Local\Packages\PythonSoftwareFoundation.Python.3.11_qbz5n2kfra8p0\LocalCache\local-packages\Python311\site-packages\telebot\__init__.py", line 1040, in polling
    logger.info('Starting your bot with username: [@%s]', self.user.username)
                                                          ^^^^^^^^^
  File "C:\Users\qpjlygujlkOo\AppData\Local\Packages\PythonSoftwareFoundation.Python.3.11_qbz5n2kfra8p0\LocalCache\local-packages\Python311\site-packages\telebot\__init__.py", line 273, in user
    self._user = self.get_me()
                 ^^^^^^^^^^^^^
  File "C:\Users\qpjlygujlkOo\AppData\Local\Packages\PythonSoftwareFoundation.Python.3.11_qbz5n2kfra8p0\LocalCache\local-packages\Python311\site-packages\telebot\__init__.py", line 1236, in get_me
    result = apihelper.get_me(self.token)
             ^^^^^^^^^^^^^^^^^^^^^^^^^^^^
  File "C:\Users\qpjlygujlkOo\AppData\Local\Packages\PythonSoftwareFoundation.Python.3.11_qbz5n2kfra8p0\LocalCache\local-packages\Python311\site-packages\telebot\apihelper.py", line 196, in get_me
    return _make_request(token, method_url)
           ^^^^^^^^^^^^^^^^^^^^^^^^^^^^^^^^
  File "C:\Users\qpjlygujlkOo\AppData\Local\Packages\PythonSoftwareFoundation.Python.3.11_qbz5n2kfra8p0\LocalCache\local-packages\Python311\site-packages\telebot\apihelper.py", line 162, in _make_request
    json_result = _check_result(method_name, result)
                  ^^^^^^^^^^^^^^^^^^^^^^^^^^^^^^^^^^
  File "C:\Users\qpjlygujlkOo\AppData\Local\Packages\PythonSoftwareFoundation.Python.3.11_qbz5n2kfra8p0\LocalCache\local-packages\Python311\site-packages\telebot\apihelper.py", line 189, in _check_result
    raise ApiTelegramException(method_name, result, result_json)
telebot.apihelper.ApiTelegramException: A request to the Telegram API was unsuccessful. Error code: 401. Description: Unauthorized

